Workbook

Sheet Cover
B2: DELHIVERY LIMITED
B3: Equity Research - Financial Model
B4: NSE: DELHIVERY
B6: Analyst | C6: Adarsh Baranwal
B7: Date | C7: 46269
B9: Recommendation | C9: HOLD (Preliminary)
B10: Current Price | C10: 457.9
B11: Price Target (Base Case) | C11: TBD - Week 2
B12: Upside / Downside | C12: TBD - Week 2

Sheet Assumptions
A3: DELHIVERY ASSUMPTIONS
B4: Unit
A6: MARKET DATA
A7: Share Price (04-09-2026) | B7: ₹ | C7: =Cover!C10 -> 457.9
A8: Shares Outstanding | B8: Mn | C8: ='Income Statement'!H26/'Income Statement'!H28*10 -> 753.38235
A9: Market Cap | B9: ₹ Cr | C9: =C7*C8/10 -> 34497.378
C11: FY27E | D11: FY28E | E11: FY29E
A13: INCOME STATEMENT ASSUMPTIONS
A15: Revenue Growth %
A16: Bear Case | B16: % | C16: 0.2 | D16: 0.15 | E16: 0.12
A17: Base Case | B17: % | C17: 0.25 | D17: 0.2 | E17: 0.18
A18: Bull Case | B18: % | C18: 0.3 | D18: 0.25 | E18: 0.22
A20: Operating Expenses as % of Revenue
A21: Bear Case | B21: % | C21: 0.92 | D21: 0.91 | E21: 0.905
A22: Base Case | B22: % | C22: 0.91 | D22: 0.895 | E22: 0.885
A23: Bull Case | B23: % | C23: 0.895 | D23: 0.875 | E23: 0.86
A25: Depreciation
A26: Bear Case | B26: ₹ Cr | C26: 780 | D26: 820 | E26: 850
A27: Base Case | B27: ₹ Cr | C27: 750 | D27: 780 | E27: 800
A28: Bull Case | B28: ₹ Cr | C28: 720 | D28: 740 | E28: 750
A30: Finance Costs
A31: Bear Case | B31: ₹ Cr | C31: 160 | D31: 170 | E31: 175
A32: Base Case | B32: ₹ Cr | C32: 150 | D32: 155 | E32: 155
A33: Bull Case | B33: ₹ Cr | C33: 140 | D33: 135 | E33: 130
A35: Other Income
A36: Bear Case | B36: ₹ Cr | C36: 280 | D36: 290 | E36: 300
A37: Base Case | B37: ₹ Cr | C37: 300 | D37: 310 | E37: 320
A38: Bull Case | B38: ₹ Cr | C38: 320 | D38: 340 | E38: 360
A40: Tax Rate %
A41: Bear Case | B41: % | C41: 0.15 | D41: 0.2 | E41: 0.25
A42: Base Case | B42: % | C42: 0.1 | D42: 0.15 | E42: 0.22
A43: Bull Case | B43: % | C43: 0.05 | D43: 0.1 | E43: 0.18
A46: BALANCE SHEET ASSUMPTIONS
A48: Equity Capital | B48: ₹ Cr | C48: ='Balance Sheet'!$H$6 -> 75 | D48: ='Balance Sheet'!$H$6 -> 75 | E48: ='Balance Sheet'!$H$6 -> 75
A50: Borrowings | B50: ₹ Cr | C50: ='Balance Sheet'!$H$10 -> 1463 | D50: ='Balance Sheet'!$H$10 -> 1463 | E50: ='Balance Sheet'!$H$10 -> 1463
A52: Other Liabilities Growth % | B52: % | C52: 0.1 | D52: 0.1 | E52: 0.1
A54: CWIP | B54: ₹ Cr | C54: ='Balance Sheet'!$H$17 -> 1 | D54: ='Balance Sheet'!$H$17 -> 1 | E54: ='Balance Sheet'!$H$17 -> 1
A56: Investments | B56: ₹ Cr | C56: ='Balance Sheet'!$H$18 -> 2961 | D56: ='Balance Sheet'!$H$18 -> 2961 | E56: ='Balance Sheet'!$H$18 -> 2961
A58: Other Assets Growth %
A59: Bear Case | B59: % | C59: =C16 -> 0.2 | D59: =D16 -> 0.15 | E59: =E16 -> 0.12
...

Sheet Income Statement
B3: Unit | C3: FY21 | D3: FY22 | E3: FY23 | F3: FY24 | G3: FY25 | H3: FY26 | I3: FY27E | J3: FY28E | K3: FY29E
A5: INCOME
A6: Revenue from Operations | B6: ₹ Cr | C6: 3647 | D6: 6882 | E6: 7225 | F6: 8142 | G6: 8932 | H6: 10508 | I6: =H6*(1+Assumptions!C17) -> 13135 | J6: =I6*(1+Assumptions!D17) -> 15762 | K6: =J6*(1+Assumptions!E17) -> 18599.16
A7: Revenue Growth | B7: % | D7: =(D6-C6)/C6 -> 0.88703044 | E7: =(E6-D6)/D6 -> 0.049840163 | F7: =(F6-E6)/E6 -> 0.12692042 | G7: =(G6-F6)/F6 -> 0.097027757 | H7: =(H6-G6)/G6 -> 0.17644425 | I7: =(I6-H6)/H6 -> 0.25 | J7: =(J6-I6)/I6 -> 0.2 | K7: =(K6-J6)/J6 -> 0.18
A8: Other Income | B8: ₹ Cr | C8: 150 | D8: 156 | E8: 319 | F8: 439 | G8: 442 | H8: 340 | I8: =Assumptions!C37 -> 300 | J8: =Assumptions!D37 -> 310 | K8: =Assumptions!E37 -> 320
A9: Total Income | B9: ₹ Cr | C9: =C6+C8 -> 3797 | D9: =D6+D8 -> 7038 | E9: =E6+E8 -> 7544 | F9: =F6+F8 -> 8581 | G9: =G6+G8 -> 9374 | H9: =H6+H8 -> 10848 | I9: =I6+I8 -> 13435 | J9: =J6+J8 -> 16072 | K9: =K6+K8 -> 18919.16
A11: EXPENSES
A12: Total Operating Expenses | B12: ₹ Cr | C12: 3769 | D12: 7357 | E12: 7677 | F12: 8015 | G12: 8556 | H12: 9868 | I12: =I6*Assumptions!C22 -> 11952.85 | J12: =J6*Assumptions!D22 -> 14106.99 | K12: =K6*Assumptions!E22 -> 16460.257
A14: PROFITABILITY
A15: EBITDA | B15: ₹ Cr | C15: =C6-C12 -> -122 | D15: =D6-D12 -> -475 | E15: =E6-E12 -> -452 | F15: =F6-F12 -> 127 | G15: =G6-G12 -> 376 | H15: =H6-H12 -> 640 | I15: =I6-I12 -> 1182.15 | J15: =J6-J12 -> 1655.01 | K15: =K6-K12 -> 2138.9034
A16: EBITDA Margin % | B16: % | C16: =C15/C6 -> -0.033452152 | D16: =D15/D6 -> -0.069020634 | E16: =E15/E6 -> -0.062560554 | F16: =F15/F6 -> 0.015598133 | G16: =G15/G6 -> 0.042095835 | H16: =H15/H6 -> 0.060905976 | I16: =I15/I6 -> 0.09 | J16: =J15/J6 -> 0.105 | K16: =K15/K6 -> 0.115
A18: Less: Depreciation and Amortisation | B18: ₹ Cr | C18: 355 | D18: 611 | E18: 831 | F18: 722 | G18: 535 | H18: 695 | I18: =Assumptions!C27 -> 750 | J18: =Assumptions!D27 -> 780 | K18: =Assumptions!E27 -> 800
A19: EBIT | B19: ₹ Cr | C19: =C15-C18 -> -477 | D19: =D15-D18 -> -1086 | E19: =E15-E18 -> -1283 | F19: =F15-F18 -> -595 | G19: =G15-G18 -> -159 | H19: =H15-H18 -> -55 | I19: =I15-I18 -> 432.15 | J19: =J15-J18 -> 875.01 | K19: =K15-K18 -> 1338.9034
A20: EBIT Margin % | B20: % | C20: =C19/C6 -> -0.13079243 | D20: =D19/D6 -> -0.15780296 | E20: =E19/E6 -> -0.17757785 | F20: =F19/F6 -> -0.073077868 | G20: =G19/G6 -> -0.017801164 | H20: =H19/H6 -> -0.0052341073 | I20: =I19/I6 -> 0.032900647 | J20: =J19/J6 -> 0.055513894 | K20: =K19/K6 -> 0.071987305
A22: Less: Finance Costs | B22: ₹ Cr | C22: 89 | D22: 100 | E22: 89 | F22: 89 | G22: 126 | H22: 144 | I22: =Assumptions!C32 -> 150 | J22: =Assumptions!D32 -> 155 | K22: =Assumptions!E32 -> 155
A23: PBT | B23: ₹ Cr | C23: =C19-C22+C8 -> -416 | D23: =D19-D22+D8 -> -1030 | E23: =E19-E22+E8 -> -1053 | F23: =F19-F22+F8 -> -245 | G23: =G19-G22+G8 -> 157 | H23: =H19-H22+H8 -> 141 | I23: =I19-I22+I8 -> 582.15 | J23: =J19-J22+J8 -> 1030.01 | K23: =K19-K22+K8 -> 1503.9034
A24: Tax Rate % | B24: % | C24: 0 | D24: -0.02 | E24: -0.04 | F24: 0.02 | G24: -0.03 | H24: -0.09 | I24: =Assumptions!C42 -> 0.1 | J24: =Assumptions!D42 -> 0.15 | K24: =Assumptions!E42 -> 0.22
A25: Tax | B25: ₹ Cr | C25: =ABS(C23)*C24 -> 0 | D25: =ABS(D23)*D24 -> -20.6 | E25: =ABS(E23)*E24 -> -42.12 | F25: =ABS(F23)*F24 -> 4.9 | G25: =ABS(G23)*G24 -> -4.71 | H25: =ABS(H23)*H24 -> -12.69 | I25: =ABS(I23)*I24 -> 58.215 | J25: =ABS(J23)*J24 -> 154.5015 | K25: =ABS(K23)*K24 -> 330.85875
A26: PAT | B26: ₹ Cr | C26: =C23-C25 -> -416 | D26: =D23-D25 -> -1009.4 | E26: =E23-E25 -> -1010.88 | F26: =F23-F25 -> -249.9 | G26: =G23-G25 -> 161.71 | H26: =H23-H25 -> 153.69 | I26: =I23-I25 -> 523.935 | J26: =J23-J25 -> 875.5085 | K26: =K23-K25 -> 1173.0447
A27: PAT Margin % | B27: % | C27: =C26/C6 -> -0.11406636 | D27: =D26/D6 -> -0.14667248 | E27: =E26/E6 -> -0.13991419 | F27: =F26/F6 -> -0.030692704 | G27: =G26/G6 -> 0.018104568 | H27: =H26/H6 -> 0.014625999 | I27: =I26/I6 -> 0.039888466 | J27: =J26/J6 -> 0.055545521 | K27: =K26/K6 -> 0.063069765
A28: EPS | B28: ₹ | C28: -2492.6 | D28: -15.75 | E28: -13.83 | F28: -3.38 | G28: 2.17 | H28: 2.04 | I28: =I26/Assumptions!$C$8*10 -> 6.9544369 | J28: =J26/Assumptions!$C$8*10 -> 11.621038 | K28: =K26/Assumptions!$C$8*10 -> 15.570376
A30: *Projection methodology note:
A31: All FY27E-FY29E figures are base case only.
A32: Bear and Bull scenarios in Scenario Summary tab.
A33: Tax rate assumptions in Assumptions tab.

Sheet Balance Sheet
B3: Units | C3: FY21 | D3: FY22 | E3: FY23 | F3: FY24 | G3: FY25 | H3: FY26 | I3: FY27E | J3: FY28E | K3: FY29E
A5: LIABILITIES
A6: Equity Capital | B6: ₹ Cr | C6: 2 | D6: 64 | E6: 73 | F6: 74 | G6: 75 | H6: 75 | I6: =Assumptions!C48 -> 75 | J6: =Assumptions!D48 -> 75 | K6: =Assumptions!E48 -> 75
A7: Reserves and Surplus | B7: ₹ Cr | C7: 2800 | D7: 5893 | E7: 9104 | F7: 9071 | G7: 9358 | H7: 9612 | I7: =H7+'Income Statement'!I26 -> 10135.935 | J7: =I7+'Income Statement'!J26 -> 11011.443 | K7: =J7+'Income Statement'!K26 -> 12184.488
A8: Total Equity | B8: ₹ Cr | C8: =C6+C7 -> 2802 | D8: =D6+D7 -> 5957 | E8: =E6+E7 -> 9177 | F8: =F6+F7 -> 9145 | G8: =G6+G7 -> 9433 | H8: =H6+H7 -> 9687 | I8: =I6+I7 -> 10210.935 | J8: =J6+J7 -> 11086.443 | K8: =K6+K7 -> 12259.488
A10: Borrowings | B10: ₹ Cr | C10: 1152 | D10: 1102 | E10: 923 | F10: 1169 | G10: 1422 | H10: 1463 | I10: =Assumptions!C50 -> 1463 | J10: =Assumptions!D50 -> 1463 | K10: =Assumptions!E50 -> 1463
A11: Other Liabilities | B11: ₹ Cr | C11: 644 | D11: 1192 | E11: 1090 | F11: 1139 | G11: 1209 | H11: 1627 | I11: =H11*(1+Assumptions!C52) -> 1789.7 | J11: =I11*(1+Assumptions!D52) -> 1968.67 | K11: =J11*(1+Assumptions!E52) -> 2165.537
A12: Total Liabilities | B12: ₹ Cr | C12: =C8+C10+C11 -> 4598 | D12: =D8+D10+D11 -> 8251 | E12: =E8+E10+E11 -> 11190 | F12: =F8+F10+F11 -> 11453 | G12: =G8+G10+G11 -> 12064 | H12: =H8+H10+H11 -> 12777 | I12: =I8+I10+I11 -> 13463.635 | J12: =J8+J10+J11 -> 14518.113 | K12: =K8+K10+K11 -> 15888.025
A14: ASSETS
A15: Fixed Assets (Net Block) | B15: ₹ Cr | C15: 1053 | D15: 3052 | E15: 2995 | F15: 3354 | G15: 3887 | H15: 5432 | I15: =H15+'Cash Flow'!I15-'Income Statement'!I18 -> 5207.4 | J15: =I15+'Cash Flow'!J15-'Income Statement'!J18 -> 4979.07 | K15: =J15+'Cash Flow'!K15-'Income Statement'!K18 -> 4774.2431
A16: Fixed Assets Growth | B16: % | D16: =(D15-C15)/C15 -> 1.8983856 | E16: =(E15-D15)/D15 -> -0.018676278 | F16: =(F15-E15)/E15 -> 0.11986644 | G16: =(G15-F15)/F15 -> 0.15891473 | H16: =(H15-G15)/G15 -> 0.39747878 | I16: =(I15-H15)/H15 -> -0.04134757 | J16: =(J15-I15)/I15 -> -0.043847217 | K16: =(K15-J15)/J15 -> -0.041137578
A17: CWIP | B17: ₹ Cr | C17: 77 | D17: 60 | E17: 23 | F17: 29 | G17: 33 | H17: 1 | I17: =Assumptions!C54 -> 1 | J17: =Assumptions!D54 -> 1 | K17: =Assumptions!E54 -> 1
A18: Investments | B18: ₹ Cr | C18: 1128 | D18: 2091 | E18: 2094 | F18: 2776 | G18: 3578 | H18: 2961 | I18: =Assumptions!C56 -> 2961 | J18: =Assumptions!D56 -> 2961 | K18: =Assumptions!E56 -> 2961
A19: Other Assets | B19: ₹ Cr | C19: 2340 | D19: 3048 | E19: 6078 | F19: 5295 | G19: 4565 | H19: 4383 | I19: =H19*(1+Assumptions!C60) -> 5478.75 | J19: =I19*(1+Assumptions!D60) -> 6574.5 | K19: =J19*(1+Assumptions!E60) -> 7757.91
A20: Total Assets | B20: ₹ Cr | C20: =C15+C17+C18+C19 -> 4598 | D20: =D15+D17+D18+D19 -> 8251 | E20: =E15+E17+E18+E19 -> 11190 | F20: =F15+F17+F18+F19 -> 11454 | G20: =G15+G17+G18+G19 -> 12063 | H20: =H15+H17+H18+H19 -> 12777 | I20: =I15+I17+I18+I19 -> 13648.15 | J20: =J15+J17+J18+J19 -> 14515.57 | K20: =K15+K17+K18+K19 -> 15494.153
A22: Balance Check | B22: ₹ Cr | C22: =C20-C12 -> 0 | D22: =D20-D12 -> 0 | E22: =E20-E12 -> 0 | F22: =F20-F12 -> 1 | G22: =G20-G12 -> -1 | H22: =H20-H12 -> 0 | I22: =I20-I12 -> 184.515 | J22: =J20-J12 -> -2.5435 | K22: =K20-K12 -> -393.87203
A24: KEY RATIOS
A25: Debt / Equity | B25: x | C25: =C10/C8 -> 0.4111349 | D25: =D10/D8 -> 0.18499245 | E25: =E10/E8 -> 0.10057753 | F25: =F10/F8 -> 0.12782941 | G25: =G10/G8 -> 0.15074738 | H25: =H10/H8 -> 0.15102715 | I25: =I10/I8 -> 0.14327777 | J25: =J10/J8 -> 0.13196297 | K25: =K10/K8 -> 0.11933614
A26: Cash | B26: ₹ Cr | C26: 277 | D26: 229 | E26: 645 | F26: 403 | G26: 336 | H26: 244 | I26: =H26+'Cash Flow'!I11 -> 725.3725 | J26: =I26+'Cash Flow'!J11 -> 1558.616 | K26: =J26+'Cash Flow'!K11 -> 2662.9854
A27: Net Debt | B27: ₹ Cr | C27: =C10-C26 -> 875 | D27: =D10-D26 -> 873 | E27: =E10-E26 -> 278 | F27: =F10-F26 -> 766 | G27: =G10-G26 -> 1086 | H27: =H10-H26 -> 1219 | I27: =I10-I26 -> 737.6275 | J27: =J10-J26 -> -95.616 | K27: =K10-K26 -> -1199.9854

Sheet Cash Flow
B3: Units | C3: FY21 | D3: FY22 | E3: FY23 | F3: FY24 | G3: FY25 | H3: FY26 | I3: FY27E | J3: FY28E | K3: FY29E
A5: CASH FLOWS
A6: Cash from Operating Activity (CFO) | B6: ₹ Cr | C6: 5 | D6: -241 | E6: -30 | F6: 472 | G6: 567 | H6: 911 | I6: ='Income Statement'!I15-'Income Statement'!I25-'Income Statement'!I22+I17 -> 1006.7725 | J6: ='Income Statement'!J15-'Income Statement'!J25-'Income Statement'!J22+J17 -> 1384.9135 | K6: ='Income Statement'!K15-'Income Statement'!K25-'Income Statement'!K22+K17 -> 1699.5426
A7: Cash from Investing Activity (CFI) | B7: ₹ Cr | C7: 338 | D7: -2742 | E7: -3408 | F7: -99 | G7: -102 | H7: -474 | I7: =-I15 -> -525.4 | J7: =-J15 -> -551.67 | K7: =-K15 -> -595.17312
A8: Cash from Financing Activity (CFF) | B8: ₹ Cr | C8: -147 | D8: 2902 | E8: 3538 | F8: -366 | G8: -432 | H8: -532 | I8: =-Assumptions!C66*'Income Statement'!I6 -> -630.48 | J8: =-Assumptions!D66*'Income Statement'!J6 -> -756.576 | K8: =-Assumptions!E66*'Income Statement'!K6 -> -892.75968
A10: Net Cash Flow | B10: ₹ Cr | C10: =C6+C7+C8 -> 196 | D10: =D6+D7+D8 -> -81 | E10: =E6+E7+E8 -> 100 | F10: =F6+F7+F8 -> 7 | G10: =G6+G7+G8 -> 33 | H10: =H6+H7+H8 -> -95 | I10: =I6+I7+I8 -> -149.1075 | J10: =J6+J7+J8 -> 76.6675 | K10: =K6+K7+K8 -> 211.60975
A11: Free Cash Flow | B11: ₹ Cr | C11: -244 | D11: -780 | E11: -624 | F11: 4 | G11: 92 | H11: 506 | I11: =I6-I15 -> 481.3725 | J11: =J6-J15 -> 833.2435 | K11: =K6-K15 -> 1104.3694
A12: CFO/Operating Profit % | B12: % | C12: -0.19 | D12: 0.48 | E12: -0.09 | F12: 4.02 | G12: 1.58 | H12: 1.46 | I12: =I6/'Income Statement'!I19 -> 2.329683 | J12: =J6/'Income Statement'!J19 -> 1.5827402 | K12: =K6/'Income Statement'!K19 -> 1.2693541
A14: KEY OBSERVATIONS
A15: Capex | B15: ₹ Cr | C15: 251 | D15: 544 | E15: 601 | F15: 565 | G15: 483 | H15: 422 | I15: =Assumptions!C70*'Income Statement'!I6 -> 525.4 | J15: =Assumptions!D70*'Income Statement'!J6 -> 551.67 | K15: =Assumptions!E70*'Income Statement'!K6 -> 595.17312
A16: Capex as % of Revenue | B16: % | C16: =C15/'Income Statement'!C6 -> 0.068823691 | D16: =D15/'Income Statement'!D6 -> 0.079046789 | E16: =E15/'Income Statement'!E6 -> 0.083183391 | F16: =F15/'Income Statement'!F6 -> 0.069393269 | G16: =G15/'Income Statement'!G6 -> 0.054075235 | H16: =H15/'Income Statement'!H6 -> 0.040159878 | I16: =I15/'Income Statement'!I6 -> 0.04 | J16: =J15/'Income Statement'!J6 -> 0.035 | K16: =K15/'Income Statement'!K6 -> 0.032
A17: Working Capital Changes | B17: ₹ Cr | C17: -40 | D17: -495 | E17: 64 | F17: 15 | G17: -25 | H17: 35 | I17: =Assumptions!C73*'Income Statement'!I6 -> 32.8375 | J17: =Assumptions!D73*'Income Statement'!J6 -> 39.405 | K17: =Assumptions!E73*'Income Statement'!K6 -> 46.4979
A18: WC Change as % of Revenue | B18: % | C18: =C17/'Income Statement'!C6 -> -0.010967919 | D18: =D17/'Income Statement'!D6 -> -0.071926765 | E18: =E17/'Income Statement'!E6 -> 0.0088581315 | F18: =F17/'Income Statement'!F6 -> 0.0018422992 | G18: =G17/'Income Statement'!G6 -> -0.0027989252 | H18: =H17/'Income Statement'!H6 -> 0.0033307956 | I18: =I17/'Income Statement'!I6 -> 0.0025 | J18: =J17/'Income Statement'!J6 -> 0.0025 | K18: =K17/'Income Statement'!K6 -> 0.0025
A19: FCF Margin % | B19: % | C19: =C11/'Income Statement'!C6 -> -0.066904305 | D19: =D11/'Income Statement'!D6 -> -0.11333915 | E19: =E11/'Income Statement'!E6 -> -0.086366782 | F19: =F11/'Income Statement'!F6 -> 0.00049127978 | G19: =G11/'Income Statement'!G6 -> 0.010300045 | H19: =H11/'Income Statement'!H6 -> 0.048153788 | I19: =I11/'Income Statement'!I6 -> 0.036648078 | J19: =J11/'Income Statement'!J6 -> 0.052864072 | K19: =K11/'Income Statement'!K6 -> 0.059377382

Sheet Unit Economics
A3: DELHIVERY - UNIT ECONOMICS
A5: Quarter | B5: Express Parcel Shipments (Mn) | C5: Revenue/Shipment (Rs.) | D5: EBITDA/Shipment (Rs.) | E5: Express Parcel Revenue (Rs. Cr) | F5: Express Parcel EBITDA (Rs. Cr) | G5: Total Revenue (Rs. Cr) | H5: Adj EBITDA (Rs. Cr)
A6: Q1 FY23 | B6: 152 | C6: 69.14 | D6: -0.39 | E6: 1051 | F6: -6 | G6: 1746 | H6: -217
A7: Q2 FY23 | B7: 161 | C7: 69.88 | D7: 5.34 | E7: 1125 | F7: 86 | G7: 1796 | H7: -125
A8: Q3 FY23 | B8: 170 | C8: 70.59 | D8: 8.18 | E8: 1200 | F8: 139 | G8: 1822 | H8: -67
A9: Q4 FY23 | B9: 180 | C9: 65.39 | D9: 11.39 | E9: 1177 | F9: 205 | G9: 1860 | H9: 6
A10: Q1 FY24 | B10: 182 | C10: 66.04 | D10: 11.92 | E10: 1202 | F10: 217 | G10: 1930 | H10: -25
A11: Q2 FY24 | B11: 181 | C11: 66.85 | D11: 11.22 | E11: 1210 | F11: 203 | G11: 1942 | H11: -13
A12: Q3 FY24 | B12: 201 | C12: 72.04 | D12: 14.88 | E12: 1448 | F12: 299 | G12: 2194 | H12: 92
A13: Q4 FY24 | B13: 176 | C13: 69.15 | D13: 12.16 | E13: 1217 | F13: 214 | G13: 2076 | H13: 21
A14: Q1 FY25 | B14: 183 | C14: 69.73 | D14: 12.68 | E14: 1276 | F14: 232 | G14: 2172 | H14: 37
A15: Q2 FY25 | B15: 185 | C15: 70.16 | D15: 10.59 | E15: 1298 | F15: 196 | G15: 2190 | H15: 10
A16: Q3 FY25 | B16: 206 | C16: 72.23 | D16: 11.26 | E16: 1488 | F16: 232 | G16: 2378 | H16: 45
A17: Q4 FY25 | B17: 177 | C17: 70.96 | D17: 11.3 | E17: 1256 | F17: 200 | G17: 2192 | H17: 55
... A22: Q1 FY27 | B22: 322 | C22: 58.04 | D22: 9.07 | E22: 1869 | F22: 292 | G22: 2931 | H22: 76

Sheet Comps
A3: DELHIVERY - COMPETITIVE LANDSCAPE ANALYSIS
B4: Unit | C4: Bluedart | D4: Shadowfax | E4: TCI Express | F4: Shiprocket | G4: Delhivery
A6: FY26 Revenue | B6: ₹ Cr | C6: 6141 | D6: 4080 | E6: 1236 | F6: 2024 | G6: ='Income Statement'!H6 -> 10508
A7: FY26 EBITDA | B7: ₹ Cr | C7: 951 | D7: 214 | E7: 132 | F7: -67 | G7: ='Income Statement'!H15 -> 640
A8: FY26 EBITDA Margin % | B8: % | C8: =C7/C6 -> 0.15486077 | D8: =D7/D6 -> 0.05245098 | E8: =E7/E6 -> 0.10679612 | F8: =F7/F6 -> -0.033102767 | G8: =G7/G6 -> 0.060905976
A9: FY26 PAT | B9: ₹ Cr | C9: 247 | D9: 115 | E9: 90 | F9: -79 | G9: ='Income Statement'!H26 -> 153.69
A10: FY26 EPS | B10: ₹ | C10: 104.26 | D10: 1.98 | E10: 23.38 | F10: -1.25 | G10: ='Income Statement'!H28 -> 2.04
A11: Revenue Growth % (FY26 vs FY25) | B11: % | C11: =C6/5720-1 -> 0.073601399 | D11: =D6/2467-1 -> 0.65383056 | E11: =E6/1208-1 -> 0.023178808 | F11: =2024/1632-1 -> 0.24019608 | G11: ='Income Statement'!H7 -> 0.17644425
A12: Market Cap | B12: ₹ Cr | C12: 11485 | D12: 14750 | E12: =2021 -> 2021 | F12: 9644 | G12: =Assumptions!C9 -> 34497.378
A13: Total Debt | B13: ₹ Cr | C13: 1142 | D13: 234 | E13: 30 | F13: 345 | G13: ='Balance Sheet'!H10 -> 1463
A14: Cash | B14: ₹ Cr | C14: 239 | D14: 673 | E14: 15 | F14: 188 | G14: ='Balance Sheet'!H26 -> 244
A15: Enterprise Value | B15: ₹ Cr | C15: =C12+C13-C14 -> 12388 | D15: =D12+D13-D14 -> 14311 | E15: =E12+E13-E14 -> 2036 | F15: =F12+F13-F14 -> 9801 | G15: =G12+G13-G14 -> 35716.378
A16: Trailing P/E FY26 | B16: x | C16: =C12/C9 -> 46.497976 | D16: =D12/D9 -> 128.26087 | E16: =E12/E9 -> 22.455556 | F16: =F12/F9 -> -122.07595 | G16: =G12/G9 -> 224.46078
A17: EV/EBITDA | B17: x | C17: =C15/C7 -> 13.026288 | D17: =D15/D7 -> 66.873832 | E17: =E15/E7 -> 15.424242 | F17: =F15/F7 -> -146.28358 | G17: =G15/G7 -> 55.806841
A18: Forward P/E FY27E (estimate for peers) | B18: x | C18: =C12/(C9*(1+C11)) -> 43.310279 | D18: =D12/(D9*(1+D11)) -> 77.553815 | E18: =E12/(E9*(1+E11)) -> 21.946854 | F18: =F12/(F9*(1+F11)) -> -98.432781 | G18: ='Scenario Summary'!C46 -> 65.842858
A19: Forward PEG Ratio (P/E / Revenue Growth %) | B19: % | C19: =C18/C11/100 -> 5.8844369 | D19: =D18/D11/100 -> 1.1861455 | E19: =E18/E11/100 -> 9.4684997 | F19: =F18/F11/100 -> -4.0980178 | G19: =G18/G11/100 -> 3.7316523
A20: FCF | B20: ₹ Cr | C20: 498 | D20: 158 | E20: 25 | F20: 35 | G20: ='Cash Flow'!H11 -> 506
A21: FCF Yield % (FCF / Market Cap) | B21: % | C21: =C20/C12 -> 0.043360906 | D21: =D20/D12 -> 0.010711864 | E21: =E20/E12 -> 0.012370114 | F21: =F20/F12 -> 0.0036291995 | G21: =G20/G12 -> 0.014667781
A22: FCF Margin % (FCF / Revenue) | B22: % | C22: =C20/C6 -> 0.081094284 | D22: =D20/D6 -> 0.03872549 | E22: =E20/E6 -> 0.020226537 | F22: =F20/F6 -> 0.01729249 | G22: =G20/G6 -> 0.048153788
A25: NOTES:
A26: Shiprocket P/E and EV/EBITDA not meaningful - negative EBITDA/PAT in FY26
A27: Delhivery trailing P/E of 224x not meaningul - use forward P/E for valuation
A28: Forward P/E for peers estimated using FY26 PAT x (1+Revenue Growth %)
A29: Delhivery Forward P/E FY 27E: 66x | FY28E: 39x (from financial model)
A30: All data as of FY26 annual results. Market Cap as of September 2026
A31: FCF sourced from Screener.in cash flow statements

Sheet DCF
A3: DELHIVERY - DCF VALUATION
A5: DCF INPUTS
A6: WACC | B6: % | C6: 0.13
A7: Terminal Growth Rate | B7: % | C7: 0.04
A8: Net Debt (FY26) | B8: ₹ | C8: ='Balance Sheet'!H27 -> 1219
A9: Shares Outstanding | B9: Mn | C9: =Assumptions!C8 -> 753.38235
B11: Unit | C11: FY27E | D11: FY28E | E11: FY29E | F11: FY30E | G11: FY31E | H11: Terminal
A12: BASE CASE DCF
A14: FCF | B14: ₹ Cr | C14: ='Scenario Summary'!C38 -> 481.3725 | D14: ='Scenario Summary'!D38 -> 833.2435 | E14: ='Scenario Summary'!E38 -> 1104.3694 | F14: =E14*1.15 -> 1270.0248 | G14: =F14*1.12 -> 1422.4278 | H14: =G14*(1+C7)/(C6-C7) -> 16436.944
A15: Growth Rate | B15: % | C15: =C14/'Cash Flow'!H11-1 -> -0.048670949 | D15: =D14/C14-1 -> 0.73097445 | E15: =E14/D14-1 -> 0.3253862 | F15: =F14/E14-1 -> 0.15 | G15: =G14/F14-1 -> 0.12 | H15: =C7 -> 0.04
A16: Discount Factor | C16: =1/(1+$C$6) -> 0.88495575 | D16: =1/(1+$C$6)^2 -> 0.78314668 | E16: =1/(1+$C$6)^3 -> 0.69305016 | F16: =1/(1+$C$6)^4 -> 0.61331873 | G16: =1/(1+$C$6)^5 -> 0.54275994 | H16: =G16 -> 0.54275994
A17: PV of FCF | B17: ₹ Cr | C17: =C14*C16 -> 425.99336 | D17: =D14*D16 -> 652.55188 | E17: =E14*E16 -> 765.38341 | F17: =F14*F16 -> 778.93002 | G17: =G14*G16 -> 772.03684 | H17: =H14*H16 -> 8921.3146
A19: Sum of PV of FCFs | B19: ₹ Cr | C19: =SUM(C17:G17) -> 3394.8955
A20: PV of Terminal Value | B20: ₹ Cr | C20: =H17 -> 8921.3146
A21: Enterprise Value | B21: ₹ Cr | C21: =C19+C20 -> 12316.21
A22: Less: Net Debt | B22: ₹ Cr | C22: ='Balance Sheet'!H27 -> 1219
A23: Equity Value | B23: ₹ Cr | C23: =C21-C22 -> 11097.21
A24: Shares Outstanding | B24: Mn | C24: =Assumptions!C8 -> 753.38235
A25: Intrinsic Value per Share | B25: ₹ | C25: =C23/C24*10 -> 147.29851
A26: Current Market Price | B26: ₹ | C26: =Assumptions!C7 -> 457.9
A27: Upside / Downside | B27: % | C27: =C25/C26-1 -> -0.67831729
A29: BEAR CASE DCF
A31: FCF | B31: ₹ Cr | C31: ='Scenario Summary'!C37 -> 260.5448 | D31: ='Scenario Summary'!D37 -> 470.28588 | E31: ='Scenario Summary'!E37 -> 586.87164 | F31: =E31*1.08 -> 633.82137 | G31: =F31*1.06 -> 671.85066 | H31: =G31*(1+C7)/(C6-C7) -> 7763.6076
A32: Growth Rate | B32: % | C32: =C31/'Cash Flow'!H11-1 -> -0.48508933 | D32: =D31/C31-1 -> 0.80500966 | E32: =E31/D31-1 -> 0.24790402 | F32: =F31/E31-1 -> 0.08 | G32: =G31/F31-1 -> 0.06 | H32: =C7 -> 0.04
A33: Discount Factor | C33: =1/(1+$C$6) -> 0.88495575 | D33: =1/(1+$C$6)^2 -> 0.78314668 | E33: =1/(1+$C$6)^3 -> 0.69305016 | F33: =1/(1+$C$6)^4 -> 0.61331873 | G33: =1/(1+$C$6)^5 -> 0.54275994 | H33: =G33 -> 0.54275994
A34: PV of FCF | B34: ₹ Cr | C34: =C31*C33 -> 230.57062 | D34: =D31*D33 -> 368.30283 | E34: =E31*E33 -> 406.73149 | F34: =F31*F33 -> 388.73452 | G34: =G31*G33 -> 364.65362 | H34: =H31*H33 -> 4213.7751
A36: Sum of PV of FCFs | B36: ₹ Cr | C36: =SUM(C34:G34) -> 1758.9931
A37: PV of Terminal Value | B37: ₹ Cr | C37: =H34 -> 4213.7751
A38: Enterprise Value | B38: ₹ Cr | C38: =C36+C37 -> 5972.7682
A39: Less: Net Debt | B39: ₹ Cr | C39: ='Balance Sheet'!H27 -> 1219
A40: Equity Value | B40: ₹ Cr | C40: =C38-C39 -> 4753.7682
A41: Shares Outstanding | B41: Mn | C41: =Assumptions!C8 -> 753.38235
A42: Intrinsic Value per Share | B42: ₹ | C42: =C40/C41*10 -> 63.099012
A43: Current Market Price | B43: ₹ | C43: =Assumptions!C7 -> 457.9
A44: Upside / Downside | B44: % | C44: =C42/C43-1 -> -0.86219914
A46: BULL CASE DCF
A48: FCF | B48: ₹ Cr | C48: ='Scenario Summary'!C39 -> 805.6619 | D48: ='Scenario Summary'!D39 -> 1369.9175 | E48: ='Scenario Summary'!E39 -> 1823.9074 | F48: =E48*1.2 -> 2188.6889 | G48: =F48*1.15 -> 2516.9922 | H48: =G48*(1+C7)/(C6-C7) -> 29085.244
A49: Growth Rate | B49: % | C49: =C48/'Cash Flow'!H11-1 -> 0.59221719 | D49: =D48/C48-1 -> 0.70036277 | E49: =E48/D48-1 -> 0.33139946 | F49: =F48/E48-1 -> 0.2 | G49: =G48/F48-1 -> 0.15 | H49: 0.04
A50: Discount Factor | C50: =1/(1+$C$6) -> 0.88495575 | D50: =1/(1+$C$6)^2 -> 0.78314668 | E50: =1/(1+$C$6)^3 -> 0.69305016 | F50: =1/(1+$C$6)^4 -> 0.61331873 | G50: =1/(1+$C$6)^5 -> 0.54275994 | H50: =G50 -> 0.54275994
A51: PV of FCF | B51: ₹ Cr | C51: =C48*C50 -> 712.97513 | D51: =D48*D50 -> 1072.8463 | E51: =E48*E50 -> 1264.0593 | F51: =F48*F50 -> 1342.3639 | G51: =G48*G50 -> 1366.1225 | H51: =H48*H50 -> 15786.305
...

Sheet Scenario Summary
A3: DELHIVERY - SCENARIO ANALYSIS
B4: Unit
A6: MARKET DATA
A7: Current Price | B7: ₹ | C7: =Assumptions!C7 -> 457.9
A8: Shares Outstanding | B8: Mn | C8: =Assumptions!C8 -> 753.38235
A9: Market Cap | B9: ₹ Cr | C9: =Assumptions!C9 -> 34497.378
A10: Enterprise Value | B10: ₹ Cr | C10: =C9+'Balance Sheet'!H27 -> 35716.378
A13: PROJECTIONS
C14: FY27E | D14: FY28E | E14: FY29E
A16: Revenue
A17: Bear Case | B17: ₹ Cr | C17: ='Income Statement'!$H$6*(1+Assumptions!C16) -> 12609.6 | D17: =C17*(1+Assumptions!D16) -> 14501.04 | E17: =D17*(1+Assumptions!E16) -> 16241.165
A18: Base Case | B18: ₹ Cr | C18: ='Income Statement'!$H$6*(1+Assumptions!C17) -> 13135 | D18: =C18*(1+Assumptions!D17) -> 15762 | E18: =D18*(1+Assumptions!E17) -> 18599.16
A19: Bull Case | B19: ₹ Cr | C19: ='Income Statement'!$H$6*(1+Assumptions!C18) -> 13660.4 | D19: =C19*(1+Assumptions!D18) -> 17075.5 | E19: =D19*(1+Assumptions!E18) -> 20832.11
A21: EBITDA Margin %
A22: Bear Case | B22: % | C22: =1-Assumptions!C21 -> 0.08 | D22: =1-Assumptions!D21 -> 0.09 | E22: =1-Assumptions!E21 -> 0.095
A23: Base Case | B23: % | C23: =1-Assumptions!C22 -> 0.09 | D23: =1-Assumptions!D22 -> 0.105 | E23: =1-Assumptions!E22 -> 0.115
A24: Bull Case | B24: % | C24: =1-Assumptions!C23 -> 0.105 | D24: =1-Assumptions!D23 -> 0.125 | E24: =1-Assumptions!E23 -> 0.14
A26: PAT
A27: Bear Case | B27: ₹ Cr | C27: =(C17*C22-Assumptions!C26-Assumptions!C31+Assumptions!C36)*(1-Assumptions!C41) -> 296.4528 | D27: =(D17*D22-Assumptions!D26-Assumptions!D31+Assumptions!D36)*(1-Assumptions!D41) -> 484.07488 | E27: =(E17*E22-Assumptions!E26-Assumptions!E31+Assumptions!E36)*(1-Assumptions!E41) -> 613.43299
A28: Base Case | B28: ₹ Cr | C28: =(C18*C23-Assumptions!C27-Assumptions!C32+Assumptions!C37)*(1-Assumptions!C42) -> 523.935 | D28: =(D18*D23-Assumptions!D27-Assumptions!D32+Assumptions!D37)*(1-Assumptions!D42) -> 875.5085 | E28: =(E18*E23-Assumptions!E27-Assumptions!E32+Assumptions!E37)*(1-Assumptions!E42) -> 1173.0447
A29: Bull Case | B29: ₹ Cr | C29: =(C19*C24-Assumptions!C28-Assumptions!C33+Assumptions!C38)*(1-Assumptions!C43) -> 849.6249 | D29: =(D19*D24-Assumptions!D28-Assumptions!D33+Assumptions!D38)*(1-Assumptions!D43) -> 1439.4938 | E29: =(E19*E24-Assumptions!E28-Assumptions!E33+Assumptions!E38)*(1-Assumptions!E43) -> 1965.1262
A31: EPS
A32: Bear Case | B32: ₹ | C32: =C27/Assumptions!$C$8*10 -> 3.9349581 | D32: =D27/Assumptions!$C$8*10 -> 6.4253546 | E32: =E27/Assumptions!$C$8*10 -> 8.142386
A33: Base Case | B33: ₹ | C33: =C28/Assumptions!$C$8*10 -> 6.9544369 | D33: =D28/Assumptions!$C$8*10 -> 11.621038 | E33: =E28/Assumptions!$C$8*10 -> 15.570376
A34: Bull Case | B34: ₹ | C34: =C29/Assumptions!$C$8*10 -> 11.277473 | D34: =D29/Assumptions!$C$8*10 -> 19.107081 | E34: =E29/Assumptions!$C$8*10 -> 26.084049
A36: FCF
A37: Bear Case | B37: ₹ Cr | C37: =(C17*C22-(C17*C22-Assumptions!C26-Assumptions!C31+Assumptions!C36)*Assumptions!C41-Assumptions!C31+Assumptions!$C$73*C17)-Assumptions!C69*C17 -> 260.5448 | D37: =(D17*D22-(D17*D22-Assumptions!D26-Assumptions!D31+Assumptions!D36)*Assumptions!D41-Assumptions!D31+Assumptions!$D$73*D17)-Assumptions!D69*D17 -> 470.28588 | E37: =(E17*E22-(E17*E22-Assumptions!E26-Assumptions!E31+Assumptions!E36)*Assumptions!E41-Assumptions!E31+Assumptions!$E$73*E17)-Assumptions!E69*E17 -> 586.87164
A38: Base Case | B38: ₹ Cr | C38: =(C18*C23-(C18*C23-Assumptions!C27-Assumptions!C32+Assumptions!C37)*Assumptions!C42-Assumptions!C32+Assumptions!$C$73*C18)-Assumptions!C70*C18 -> 481.3725 | D38: =(D18*D23-(D18*D23-Assumptions!D27-Assumptions!D32+Assumptions!D37)*Assumptions!D42-Assumptions!D32+Assumptions!$D$73*D18)-Assumptions!D70*D18 -> 833.2435 | E38: =(E18*E23-(E18*E23-Assumptions!E27-Assumptions!E32+Assumptions!E37)*Assumptions!E42-Assumptions!E32+Assumptions!$E$73*E18)-Assumptions!E70*E18 -> 1104.3694
A39: Bull Case | B39: ₹ Cr | C39: =(C19*C24-(C19*C24-Assumptions!C28-Assumptions!C33+Assumptions!C38)*Assumptions!C43-Assumptions!C33+Assumptions!$C$73*C19)-Assumptions!C71*C19 -> 805.6619 | D39: =(D19*D24-(D19*D24-Assumptions!D28-Assumptions!D33+Assumptions!D38)*Assumptions!D43-Assumptions!D33+Assumptions!$D$73*D19)-Assumptions!D71*D19 -> 1369.9175 | E39: =(E19*E24-(E19*E24-Assumptions!E28-Assumptions!E33+Assumptions!E38)*Assumptions!E43-Assumptions!E33+Assumptions!$E$73*E19)-Assumptions!E71*E19 -> 1823.9074
A42: VALUATION
A44: Forward P/E
A45: Bear Case | B45: x | C45: =$C$9/C27 -> 116.36719 | D45: =$C$9/D27 -> 71.264549
A46: Base Case | B46: x | C46: =$C$9/C28 -> 65.842858 | D46: =$C$9/D28 -> 39.402676
A47: Bull Case | B47: x | C47: =$C$9/C29 -> 40.603068 | D47: =$C$9/D29 -> 23.964938
A49: EV/EBITDA
A50: Bear Case | B50: x | C50: =$C$10/(C22*C17) -> 35.405939 | D50: =$C$10/(D22*D17) -> 27.366909
A51: Base Case | B51: x | C51: =$C$10/(C23*C18) -> 30.213068 | D51: =$C$10/(D23*D18) -> 21.580763
A52: Bull Case | B52: x | C52: =$C$10/(C24*C19) -> 24.90088 | D52: =$C$10/(D24*D19) -> 16.733391
A54: Price/FCF
A55: Bear Case | B55: x | C55: =$C$9/C37 -> 132.40478 | D55: =$C$9/D37 -> 73.354058
...
